Traceback (most recent call last):
  File "~/.local/lib/python3.5/site-packages/tensorflow/python/client/session.py", line 1322, in _do_call
    return fn(*args)
  File "~/.local/lib/python3.5/site-packages/tensorflow/python/client/session.py", line 1307, in _run_fn
    options, feed_dict, fetch_list, target_list, run_metadata)
  File "~/.local/lib/python3.5/site-packages/tensorflow/python/client/session.py", line 1409, in _call_tf_sessionrun
    run_metadata)
tensorflow.python.framework.errors_impl.InvalidArgumentError: In[1] is not a matrix
         [[Node: MatMulAdditionError = MatMulAdditionError[T=DT_FLOAT, transpose_a=false, transpose_b=false, _device="/job:localhost/replica:0/task:0/device:SGX:0"](Variable/read/_1, Variable_1/read/_3)]]

During handling of the above exception, another exception occurred:

Traceback (most recent call last):
  File "mae_test.py", line 30, in <module>
    sess.run(train)
  File "~/.local/lib/python3.5/site-packages/tensorflow/python/client/session.py", line 900, in run
    run_metadata_ptr)
  File "~/.local/lib/python3.5/site-packages/tensorflow/python/client/session.py", line 1135, in _run
    feed_dict_tensor, options, run_metadata)
  File "~/.local/lib/python3.5/site-packages/tensorflow/python/client/session.py", line 1316, in _do_run
    run_metadata)
  File "~/.local/lib/python3.5/site-packages/tensorflow/python/client/session.py", line 1335, in _do_call
    raise type(e)(node_def, op, message)
tensorflow.python.framework.errors_impl.InvalidArgumentError: In[1] is not a matrix
         [[Node: MatMulAdditionError = MatMulAdditionError[T=DT_FLOAT, transpose_a=false, transpose_b=false, _device="/job:localhost/replica:0/task:0/device:SGX:0"](Variable/read/_1, Variable_1/read/_3)]]

Caused by op 'MatMulAdditionError', defined at:
  File "mae_test.py", line 12, in <module>
    hypothesis = tf.mae(W, b)                   # (1x2) * (2x5) = (1x5)
  File "~/.local/lib/python3.5/site-packages/tensorflow/python/ops/math_ops.py", line 2046, in mae
    a, b, transpose_a=transpose_a, transpose_b=transpose_b, name=name)
  File "~/.local/lib/python3.5/site-packages/tensorflow/python/ops/gen_math_ops.py", line 4356, in mat_mul_addition_error
    transpose_b=transpose_b, name=name)
  File "~/.local/lib/python3.5/site-packages/tensorflow/python/framework/op_def_library.py", line 787, in _apply_op_helper
    op_def=op_def)
  File "~/.local/lib/python3.5/site-packages/tensorflow/python/framework/ops.py", line 3416, in create_op
    op_def=op_def)
  File "~/.local/lib/python3.5/site-packages/tensorflow/python/framework/ops.py", line 1742, in __init__
    self._traceback = self._graph._extract_stack()  # pylint: disable=protected-access

InvalidArgumentError (see above for traceback): In[1] is not a matrix
         [[Node: MatMulAdditionError = MatMulAdditionError[T=DT_FLOAT, transpose_a=false, transpose_b=false, _device="/job:localhost/replica:0/task:0/device:SGX:0"](Variable/read/_1, Variable_1/read/_3)]]